//===----------------------------------------------------------------------===//
//
// This source file is part of the Swift.org open source project
//
// Copyright (c) 2020 - 2021 Apple Inc. and the Swift project authors
// Licensed under Apache License v2.0 with Runtime Library Exception
//
// See https://swift.org/LICENSE.txt for license information
// See https://swift.org/CONTRIBUTORS.txt for the list of Swift project authors
//
//===----------------------------------------------------------------------===//

import Swift
@_implementationOnly import _SwiftConcurrencyShims

@available(SwiftStdlib 5.1, *)
@_silgen_name("swift_job_run")
@usableFromInline
internal func _swiftJobRun(_ job: UnownedJob,
                           _ executor: UnownedSerialExecutor) -> ()

/// A job is a unit of scheduleable work.
@available(SwiftStdlib 5.1, *)
@frozen
public struct UnownedJob: Sendable {
  private var context: Builtin.Job

  @_alwaysEmitIntoClient
  @inlinable
  public func _runSynchronously(on executor: UnownedSerialExecutor) {
      _swiftJobRun(self, executor)
  }
}

@available(SwiftStdlib 5.1, *)
@frozen
public struct UnsafeContinuation<T, E: Error>: Sendable {
  @usableFromInline internal var context: Builtin.RawUnsafeContinuation

  @_alwaysEmitIntoClient
  internal init(_ context: Builtin.RawUnsafeContinuation) {
    self.context = context
  }

  /// Resume the task awaiting the continuation by having it return normally
  /// from its suspension point.
  ///
  /// - Parameter value: The value to return from the continuation.
  ///
  /// A continuation must be resumed exactly once. If the continuation has
  /// already been resumed through this object, then the attempt to resume
  /// the continuation again will result in undefined behavior.
  ///
  /// After `resume` enqueues the task, control is immediately returned to
  /// the caller. The task will continue executing when its executor is
  /// able to reschedule it.
  @_alwaysEmitIntoClient
  public func resume(returning value: __owned T) where E == Never {
    #if compiler(>=5.5) && $BuiltinContinuation
    Builtin.resumeNonThrowingContinuationReturning(context, value)
    #else
    fatalError("Swift compiler is incompatible with this SDK version")
    #endif
  }

  /// Resume the task awaiting the continuation by having it return normally
  /// from its suspension point.
  ///
  /// - Parameter value: The value to return from the continuation.
  ///
  /// A continuation must be resumed exactly once. If the continuation has
  /// already been resumed through this object, then the attempt to resume
  /// the continuation again will result in undefined behavior.
  ///
  /// After `resume` enqueues the task, control is immediately returned to
  /// the caller. The task will continue executing when its executor is
  /// able to reschedule it.
  @_alwaysEmitIntoClient
  public func resume(returning value: __owned T) {
    #if compiler(>=5.5) && $BuiltinContinuation
    Builtin.resumeThrowingContinuationReturning(context, value)
    #else
    fatalError("Swift compiler is incompatible with this SDK version")
    #endif
  }

  /// Resume the task awaiting the continuation by having it throw an error
  /// from its suspension point.
  ///
  /// - Parameter error: The error to throw from the continuation.
  ///
  /// A continuation must be resumed exactly once. If the continuation has
  /// already been resumed through this object, then the attempt to resume
  /// the continuation again will result in undefined behavior.
  ///
  /// After `resume` enqueues the task, control is immediately returned to
  /// the caller. The task will continue executing when its executor is
  /// able to reschedule it.
  @_alwaysEmitIntoClient
  public func resume(throwing error: __owned E) {
#if compiler(>=5.5) && $BuiltinContinuation
    Builtin.resumeThrowingContinuationThrowing(context, error)
#else
    fatalError("Swift compiler is incompatible with this SDK version")
#endif
  }
}

@available(SwiftStdlib 5.1, *)
extension UnsafeContinuation {
  /// Resume the task awaiting the continuation by having it either
  /// return normally or throw an error based on the state of the given
  /// `Result` value.
  ///
  /// - Parameter result: A value to either return or throw from the
  ///   continuation.
  ///
  /// A continuation must be resumed exactly once. If the continuation has
  /// already been resumed through this object, then the attempt to resume
  /// the continuation again will trap.
  ///
  /// After `resume` enqueues the task, control is immediately returned to
  /// the caller. The task will continue executing when its executor is
  /// able to reschedule it.
  @_alwaysEmitIntoClient
  public func resume<Er: Error>(with result: Result<T, Er>) where E == Error {
    switch result {
      case .success(let val):
        self.resume(returning: val)
      case .failure(let err):
        self.resume(throwing: err)
    }
  }

  /// Resume the task awaiting the continuation by having it either
  /// return normally or throw an error based on the state of the given
  /// `Result` value.
  ///
  /// - Parameter result: A value to either return or throw from the
  ///   continuation.
  ///
  /// A continuation must be resumed exactly once. If the continuation has
  /// already been resumed through this object, then the attempt to resume
  /// the continuation again will trap.
  ///
  /// After `resume` enqueues the task, control is immediately returned to
  /// the caller. The task will continue executing when its executor is
  /// able to reschedule it.
  @_alwaysEmitIntoClient
  public func resume(with result: Result<T, E>) {
    switch result {
      case .success(let val):
        self.resume(returning: val)
      case .failure(let err):
        self.resume(throwing: err)
    }
  }

  /// Resume the task awaiting the continuation by having it return normally
  /// from its suspension point.
  ///
  /// A continuation must be resumed exactly once. If the continuation has
  /// already been resumed through this object, then the attempt to resume
  /// the continuation again will trap.
  ///
  /// After `resume` enqueues the task, control is immediately returned to
  /// the caller. The task will continue executing when its executor is
  /// able to reschedule it.
  @_alwaysEmitIntoClient
  public func resume() where T == Void {
    self.resume(returning: ())
  }
}

#if _runtime(_ObjC)

// Intrinsics used by SILGen to resume or fail continuations.
@available(SwiftStdlib 5.1, *)
@_alwaysEmitIntoClient
internal func _resumeUnsafeContinuation<T>(
  _ continuation: UnsafeContinuation<T, Never>,
  _ value: __owned T
) {
  continuation.resume(returning: value)
}

@available(SwiftStdlib 5.1, *)
@_alwaysEmitIntoClient
internal func _resumeUnsafeThrowingContinuation<T>(
  _ continuation: UnsafeContinuation<T, Error>,
  _ value: __owned T
) {
  continuation.resume(returning: value)
}

@available(SwiftStdlib 5.1, *)
@_alwaysEmitIntoClient
internal func _resumeUnsafeThrowingContinuationWithError<T>(
  _ continuation: UnsafeContinuation<T, Error>,
  _ error: __owned Error
) {
  continuation.resume(throwing: error)
}

#endif

/// The operation functions must resume the continuation *exactly once*.
///
/// The continuation will not begin executing until the operation function returns.
@available(SwiftStdlib 5.1, *)
@_alwaysEmitIntoClient
public func withUnsafeContinuation<T>(
  _ fn: (UnsafeContinuation<T, Never>) -> Void
) async -> T {
  return await Builtin.withUnsafeContinuation {
    fn(UnsafeContinuation<T, Never>($0))
  }
}

/// The operation functions must resume the continuation *exactly once*.
///
/// The continuation will not begin executing until the operation function returns.
@available(SwiftStdlib 5.1, *)
@_alwaysEmitIntoClient
public func withUnsafeThrowingContinuation<T>(
  _ fn: (UnsafeContinuation<T, Error>) -> Void
) async throws -> T {
  return try await Builtin.withUnsafeThrowingContinuation {
    fn(UnsafeContinuation<T, Error>($0))
  }
}

/// A hack to mark an SDK that supports swift_continuation_await.
@available(SwiftStdlib 5.1, *)
@_alwaysEmitIntoClient
public func _abiEnableAwaitContinuation() {
  fatalError("never use this function")
}
